<?xml version="1.0"?>
<robot  xmlns:xacro="http://www.ros.org/wiki/xacro" name="mycobot_320pi_with_gripper" >

  <link name="base_link"/>

  <link name="base">
    <visual>
      <geometry> 
       <mesh filename="package://mycobot_320pi/meshes/visual/base.dae"/>
      </geometry>
    <origin xyz = "0.0 0 0 " rpy = " 0 0 3.1415926"/>
    </visual>
    <collision>
      <geometry> 
       <mesh filename="package://mycobot_320pi/meshes/collision/base.stl"/>
      </geometry>
      <origin xyz = "0.0 0 0 " rpy = " 0 0 3.1415926"/>
      </collision>
  </link>

  <link name="link1">
    <visual>
      <geometry>
       <mesh filename="package://mycobot_320pi/meshes/visual/link1.dae"/>
      </geometry>
      <origin xyz = "0.115 -0.172 -0.086" rpy = " 0 0 3.1415926"/>
    </visual>
    <collision>
      <geometry>
       <mesh filename="package://mycobot_320pi/meshes/collision/link1.stl"/>
      </geometry>
      <origin xyz = "0.115 -0.172 -0.086" rpy = " 0 0 3.1415926"/>
    </collision>
  </link>

  <link name="link2">
    <visual>
      <geometry>       
       <mesh filename="package://mycobot_320pi/meshes/visual/link2.dae"/>
      </geometry>
      <origin xyz = "-0.075 -0.115 -0.022 " rpy = " 1.5708 0 1.5708"/>
    </visual>
    <collision>
      <geometry>       
       <mesh filename="package://mycobot_320pi/meshes/collision/link2.stl"/>
      </geometry>
      <origin xyz = "-0.075 -0.115 -0.022 " rpy = " 1.5708 0 1.5708"/>
    </collision>
  </link>

  <link name="link3">
    <visual>
      <geometry> 
       <mesh filename="package://mycobot_320pi/meshes/visual/link3.dae"/>
      </geometry>
      <origin xyz = "-0.22 -0.115 0.142 " rpy = " 1.5708 0 1.5708"/>
    </visual>
    <collision>
      <geometry> 
       <mesh filename="package://mycobot_320pi/meshes/collision/link3.stl"/>
      </geometry>
      <origin xyz = "-0.22 -0.115 0.142 " rpy = " 1.5708 0 1.5708"/>
    </collision>
  </link>

  <link name="link4">
    <visual>
      <geometry> 
       <mesh filename="package://mycobot_320pi/meshes/visual/link4.dae"/>
      </geometry>
      <origin xyz = "-0.115 0.338 -0.1435" rpy = " 1.5708 0 0"/>
    </visual>
    <collision>
      <geometry> 
       <mesh filename="package://mycobot_320pi/meshes/collision/link4.stl"/>
      </geometry>
      <origin xyz = "-0.115 0.338 -0.1435" rpy = " 1.5708 0 0"/>
    </collision>
  </link>

  <link name="link5">
    <visual>
      <geometry> 
       <mesh filename="package://mycobot_320pi/meshes/visual/link5.dae"/>
      </geometry>
      <origin xyz = "-0.1149 -0.0322  -0.482 " rpy = " 0  0 0"/>
    </visual>
    <collision>
      <geometry> 
       <mesh filename="package://mycobot_320pi/meshes/collision/link5.stl"/>
      </geometry>
      <origin xyz = "-0.1149 -0.0322  -0.482 " rpy = " 0  0 0"/>
    </collision>
  </link>

  <link name="link6">
    <visual>
      <geometry> 
       <mesh filename="package://mycobot_320pi/meshes/visual/link6.dae"/>
      </geometry>
      <origin xyz = "-0.11478 0.433 -0.15 " rpy = " 1.5708 0 0"/>
    </visual>
    <collision>
      <geometry> 
       <mesh filename="package://mycobot_320pi/meshes/collision/link6.stl"/>
      </geometry>
      <origin xyz = "-0.11478 0.433 -0.15 " rpy = " 1.5708 0 0"/>
    </collision>
  </link>

  <link name="gripper_base">
        <visual>
            <geometry> 
                <mesh filename="package://mycobot_320pi/meshes/visual/gripper_base.dae" />
            </geometry>
            <origin xyz="-0.02 0.012 -0.018 " rpy=" 0 0 1.5708" />
        </visual>
        <collision>
            <geometry> 
                <mesh filename="package://mycobot_320pi/meshes/collision/gripper_base.stl" />
            </geometry>
            <origin xyz="-0.02 0.012 -0.018 " rpy=" 0 0 1.5708" />
        </collision>
        <inertial>
            <mass value="0.1" />
            <origin xyz="0 0 0" rpy="0 0 0" />
            <inertia ixx="0.03" iyy="0.03" izz="0.03" ixy="0.0" ixz="0.0" iyz="0.0" />
        </inertial>
  </link>

  <link name="gripper_left1">
      <visual>
          <geometry> 
              <mesh filename="package://mycobot_320pi/meshes/visual/gripper_left1.dae" />
          </geometry>
          <origin xyz="0.036 -0.052 0.0 " rpy=" 0 0 1.5708" />
      </visual> 
      <collision>
          <geometry> 
              <mesh filename="package://mycobot_320pi/meshes/collision/gripper_left1.stl" />
          </geometry>
          <origin xyz="0.036 -0.052 0.0 " rpy=" 0 0 1.5708" />
      </collision>
      <inertial>
          <mass value="0.1" />
          <origin xyz="0 0 0" rpy="0 0 0" />
          <inertia ixx="0.03" iyy="0.03" izz="0.03" ixy="0.0" ixz="0.0" iyz="0.0" />
      </inertial>
  </link>

  <link name="gripper_left2">
      <visual>
          <geometry>
              <mesh filename="package://mycobot_320pi/meshes/visual/gripper_left2.dae" />
          </geometry>
          <origin xyz="0.03 0.024 -0.018 " rpy=" 0 0 1.5708" />
      </visual>  
      <collision>
          <geometry>
              <mesh filename="package://mycobot_320pi/meshes/collision/gripper_left2.stl" />
          </geometry>
          <origin xyz="0.03 0.024 -0.018 " rpy=" 0 0 1.5708" />
      </collision>
      <inertial>
          <mass value="0.1" />
          <origin xyz="0 0 0" rpy="0 0 0" />
          <inertia ixx="0.03" iyy="0.03" izz="0.03" ixy="0.0" ixz="0.0" iyz="0.0" />
      </inertial>
  </link>

  <link name="gripper_left3">
      <visual>
          <geometry>
              <mesh filename="package://mycobot_320pi/meshes/visual/gripper_left3.dae" />
          </geometry>
          <origin xyz="0.034 0.0 -0.012 " rpy=" 0 3.14159 -1.5708" /> 
      </visual> 
      <collision>
          <geometry>
              <mesh filename="package://mycobot_320pi/meshes/collision/gripper_left3.stl" />
          </geometry>
          <origin xyz="0.034 0.0 -0.012 " rpy=" 0 3.14159 -1.5708" /> 
      </collision>
      <inertial>
          <mass value="0.1" />
          <origin xyz="0 0 0" rpy="0 0 0" />
          <inertia ixx="0.03" iyy="0.03" izz="0.03" ixy="0.0" ixz="0.0" iyz="0.0" />
      </inertial>
  </link>

  <link name="gripper_right1">
      <visual>
          <geometry> 
              <mesh filename="package://mycobot_320pi/meshes/visual/gripper_right1.dae" />
          </geometry>
          <origin xyz="-0.072 -0.05 0.0 " rpy=" 0 0 1.5708" />
      </visual> 
      <collision>
          <geometry> 
              <mesh filename="package://mycobot_320pi/meshes/collision/gripper_right1.stl" />
          </geometry>
          <origin xyz="-0.072 -0.05 0.0 " rpy=" 0 0 1.5708" />
      </collision>
      <inertial>
          <mass value="0.1" />
          <origin xyz="0 0 0" rpy="0 0 0" />
          <inertia ixx="0.03" iyy="0.03" izz="0.03" ixy="0.0" ixz="0.0" iyz="0.0" />
      </inertial>
  </link>

  <link name="gripper_right2">
      <visual>
          <geometry>
              <mesh filename="package://mycobot_320pi/meshes/visual/gripper_right2.dae" />
          </geometry>
          <origin xyz="-0.066 0.023 -0.018 " rpy=" 0 0 1.5708" />
      </visual> 
      <collision>
          <geometry>
              <mesh filename="package://mycobot_320pi/meshes/collision/gripper_right2.stl" />
          </geometry>
          <origin xyz="-0.066 0.023 -0.018 " rpy=" 0 0 1.5708" />
      </collision>
      <inertial>
          <mass value="0.1" />
          <origin xyz="0 0 0" rpy="0 0 0" />
          <inertia ixx="0.03" iyy="0.03" izz="0.03" ixy="0.0" ixz="0.0" iyz="0.0" />
      </inertial>
  </link>

  <link name="gripper_right3">
      <visual>
          <geometry>
              <mesh filename="package://mycobot_320pi/meshes/visual/gripper_right3.dae" />
          </geometry>
          <origin xyz="0 0.0 -0.012 " rpy=" 0 3.14159 -1.5708" />
      </visual> 
      <collision>
          <geometry>
              <mesh filename="package://mycobot_320pi/meshes/collision/gripper_right3.stl" />
          </geometry>
          <origin xyz="0 0.0 -0.012 " rpy=" 0 3.14159 -1.5708" />
      </collision>
      <inertial>
          <mass value="0.1" />
          <origin xyz="0 0 0" rpy="0 0 0" />
          <inertia ixx="0.03" iyy="0.03" izz="0.03" ixy="0.0" ixz="0.0" iyz="0.0" />
      </inertial>
  </link>

  <joint name="base_joint" type="fixed">
    <axis xyz="0 0 1"/> 
    <parent link="base_link"/>
    <child link="base"/> 
  </joint>

  <joint name="joint_1" type="revolute">
    <axis xyz="0 0 1"/>
    <limit effort = "1000.0" lower = "-2.96" upper = "2.96" velocity = "0"/>
    <parent link="base"/>
    <child link="link1"/>
    <origin xyz= "0 0 0.162" rpy = "0 0 0"/> 
  </joint>

  <joint name="joint_2" type="revolute">
    <axis xyz="0 0 1"/>
    <limit effort = "1000.0" lower = "-2.79" upper = "2.79" velocity = "0"/>
    <parent link="link1"/>
    <child link="link2"/>
    <origin xyz= "0 0 0" rpy = "0 -1.5708 1.5708"/> 
  </joint>

  <joint name="joint_3" type="revolute">
    <axis xyz=" 0 0 1"/>
    <limit effort = "1000.0" lower = "-2.79" upper = "2.79" velocity = "0"/>
    <parent link="link2"/>
    <child link="link3"/>
    <origin xyz= "0.13635 0 0   " rpy = "0 0 0"/>  
  </joint>

  <joint name="joint_4" type="revolute">
    <axis xyz=" 0 0 1"/>
    <limit effort = "1000.0" lower = "-2.79" upper = "2.79" velocity = "0"/>
    <parent link="link3"/>
    <child link="link4"/> 
     <origin xyz = "0.1205 0 0.082 " rpy = " 0 0 1.57080"/>
  </joint>

  <joint name="joint_5" type="revolute">
    <axis xyz="0 0 1"/>
    <limit effort = "1000.0" lower = "-2.96" upper = "2.96" velocity = "0"/>
    <parent link="link4"/>
    <child link="link5"/>
     <origin xyz= "0 -0.084 0" rpy = "1.5708 0 0"/>
  </joint>

  <joint name="joint_6" type="revolute">
    <axis xyz="0 0 1"/>
    <limit effort = "1000.0" lower = "-3.05" upper = "3.05" velocity = "0"/>
    <parent link="link5"/>
    <child link="link6"/>
     <origin xyz= "0 0.06635 0" rpy = "-1.5708 0 0"/>
  </joint>

  <joint name="link6_to_gripper_base_fixed_jnt" type="fixed"> 
      <parent link="link6" />
      <child link="gripper_base" />
      <origin xyz="0 0.0 0.034" rpy="1.5708 0 0" />
  </joint>

  <joint name="mycobot_gripper_joint" type="revolute">
      <axis xyz="0 0 1" />
      <limit effort="1000.0" lower="-0.7" upper="0.3" velocity="0" />
      <parent link="gripper_base" />
      <child link="gripper_left3" />
      <origin xyz="-0.018 0.016 0" rpy="0 0 0" />
  </joint>

  <joint name="gripper_base_to_gripper_left2_mimic_jnt" type="revolute">
      <axis xyz="0 0 1" />
      <limit effort="1000.0" lower="-0.8" upper="0.5" velocity="0" />
      <parent link="gripper_base" />
      <child link="gripper_left2" />
      <origin xyz="-0.05 -0.01 0" rpy="0 0 0" />
      <mimic joint="mycobot_gripper_joint" multiplier="1.0" offset="0" />
  </joint>

  <joint name="gripper_left3_to_gripper_left1_mimic_jnt" type="revolute">
      <axis xyz="0 0 1" />
      <limit effort="1000.0" lower="-0.5" upper="0.5" velocity="0" />
      <parent link="gripper_left3" />
      <child link="gripper_left1" />
      <origin xyz="-0.0356 0.051 -0.018" rpy="0 0 0" />
      <mimic joint="mycobot_gripper_joint" multiplier="-1.0" offset="0" />
  </joint>

  <joint name="gripper_base_to_gripper_right3_mimic_jnt" type="revolute">
      <axis xyz="0 0 1" />
      <limit effort="1000.0" lower="-0.3" upper="0.7" velocity="0" />
      <parent link="gripper_base" />
      <child link="gripper_right3" />
      <origin xyz="0.018 0.016 0" rpy="0 0 0" />
      <mimic joint="mycobot_gripper_joint" multiplier="-1.0" offset="0" />
  </joint>

  <joint name="gripper_base_to_gripper_right2_mimic_jnt" type="revolute">
      <axis xyz="0 0 1" />
      <limit effort="1000.0" lower="-0.5" upper="0.8" velocity="0" />
      <parent link="gripper_base" />
      <child link="gripper_right2" />
      <origin xyz="0.046 -0.01 0" rpy="0 0 0" />
      <mimic joint="mycobot_gripper_joint" multiplier="-1.0" offset="0" />
  </joint>

  <joint name="gripper_right3_to_gripper_right1_mimic_jnt" type="revolute">
      <axis xyz="0 0 1" />
      <limit effort="1000.0" lower="-0.5" upper="0.5" velocity="0" />
      <parent link="gripper_right3" />
      <child link="gripper_right1" />
      <origin xyz="0.033 0.051 -0.018" rpy="0 0 0" />
      <mimic joint="mycobot_gripper_joint" multiplier="1.0" offset="0" />
  </joint>

</robot>
